Workbook

Sheet 类型总览
A1: 类型 | B1: 情绪组 | C1: 核心信念 | D1: 主要受众 | E1: 最适合的业务环节 | F1: 主题数 | G1: 已制作 | H1: 未制作
A2: A 时间的力量 | B2: 🔴 塑危组（制造紧迫感） | C2: 时间是最公平也最无情的资源，看得见才会珍惜 | D2: 学生（高三尤甚）+ 家长 | E2: 引流、节点塑危、社群早安 | F2: =COUNTIF(主题清单!$B$2:$B$70,A2) -> 6 | G2: =COUNTIFS(主题清单!$B$2:$B$70,A2,主题清单!$J$2:$J$70,"已制作") -> 4 | H2: =F2-G2 -> 2
A3: B 迈出第一步 | B3: 🟡 激励组（给动力） | C3: 最难的是开始，开始之后一切变轻 | D3: 学生 + 家长 | E3: 截杀（预报名/开售）、异议"再看看 / 不着急" | F3: =COUNTIF(主题清单!$B$2:$B$70,A3) -> 6 | G3: =COUNTIFS(主题清单!$B$2:$B$70,A3,主题清单!$J$2:$J$70,"已制作") -> 4 | H3: =F3-G3 -> 2
A4: C 坚持到临界点 | B4: 🟡 激励组（给动力） | C4: 质变前看起来什么都没发生，不要停在 99℃ | D4: 学生 | E4: 促出勤（第 2、3 天）、续报、异议"没效果" | F4: =COUNTIF(主题清单!$B$2:$B$70,A4) -> 6 | G4: =COUNTIFS(主题清单!$B$2:$B$70,A4,主题清单!$J$2:$J$70,"已制作") -> 5 | H4: =F4-G4 -> 1
A5: D 每天一点点 | B5: 🟡 激励组（给动力） | C5: 微小的差距，时间会把它放大 | D5: 学生 | E5: 社群早晚安、打卡、开营 | F5: =COUNTIF(主题清单!$B$2:$B$70,A5) -> 5 | G5: =COUNTIFS(主题清单!$B$2:$B$70,A5,主题清单!$J$2:$J$70,"已制作") -> 4 | H5: =F5-G5 -> 1
A6: E 集中力量 | B6: 🔵 赋能组（给方法、给信心） | C6: 分散的努力等于没努力，聚焦才能突破 | D6: 学生 + 家长 | E6: 推课做减法（多科→单科、大班→小班） | F6: =COUNTIF(主题清单!$B$2:$B$70,A6) -> 6 | G6: =COUNTIFS(主题清单!$B$2:$B$70,A6,主题清单!$J$2:$J$70,"已制作") -> 4 | H6: =F6-G6 -> 2
A7: F 方法与借力 | B7: 🔵 赋能组（给方法、给信心） | C7: 方向和方法错了，越努力越远；好老师是杠杆 | D7: 家长 + 学生 | E7: 推课塑造产品价值、异议"自己学就行" | F7: =COUNTIF(主题清单!$B$2:$B$70,A7) -> 6 | G7: =COUNTIFS(主题清单!$B$2:$B$70,A7,主题清单!$J$2:$J$70,"已制作") -> 5 | H7: =F7-G7 -> 1
A8: G 差距与竞争 | B8: 🔴 塑危组（制造紧迫感） | C8: 高考是排名，你在跑，别人也在跑 | D8: 家长 + 学生 | E8: 引流塑危、推课塑危 | F8: =COUNTIF(主题清单!$B$2:$B$70,A8) -> 5 | G8: =COUNTIFS(主题清单!$B$2:$B$70,A8,主题清单!$J$2:$J$70,"已制作") -> 4 | H8: =F8-G8 -> 1
A9: H 短板决定上限 | B9: 🔴 塑危组（制造紧迫感） | C9: 总分被最弱的一科拖住，补弱科性价比最高 | D9: 家长 + 学生 | E9: 测评/试卷分析解读、弱科推课 | F9: =COUNTIF(主题清单!$B$2:$B$70,A9) -> 4 | G9: =COUNTIFS(主题清单!$B$2:$B$70,A9,主题清单!$J$2:$J$70,"已制作") -> 2 | H9: =F9-G9 -> 2
A10: I 关键窗口期 | B10: 🔴 塑危组（制造紧迫感） | C10: 有些时间段错过就没有了（寒暑假、高一、一轮复习） | D10: 家长 + 学生 | E10: 节点物料（考后/放假/开学/百日） | F10: =COUNTIF(主题清单!$B$2:$B$70,A10) -> 8 | G10: =COUNTIFS(主题清单!$B$2:$B$70,A10,主题清单!$J$2:$J$70,"已制作") -> 6 | H10: =F10-G10 -> 2
A11: J 你也可以 | B11: 🔵 赋能组（给方法、给信心） | C11: 起点不决定终点，现在的低谷是蓄力 | D11: 成绩中下的学生 + 焦虑家长 | E11: 异议"没信心 / 孩子基础差"、学员故事 | F11: =COUNTIF(主题清单!$B$2:$B$70,A11) -> 5 | G11: =COUNTIFS(主题清单!$B$2:$B$70,A11,主题清单!$J$2:$J$70,"已制作") -> 4 | H11: =F11-G11 -> 1
A12: K 家长专属 | B12: 🔵 赋能组（给方法、给信心） | C12: 陪伴的时间所剩不多；支持要用对方式 | D12: 家长 | E12: 家长课堂、亲子不一致异议、私域维护 | F12: =COUNTIF(主题清单!$B$2:$B$70,A12) -> 8 | G12: =COUNTIFS(主题清单!$B$2:$B$70,A12,主题清单!$J$2:$J$70,"已制作") -> 7 | H12: =F12-G12 -> 1
A13: L 心态与抗压 | B13: 🔵 赋能组（给方法、给信心） | C13: 适度压力最好，稳定比冲高更重要 | D13: 学生（考前） | E13: 考前社群、考后安抚、主讲答疑会 | F13: =COUNTIF(主题清单!$B$2:$B$70,A13) -> 4 | G13: =COUNTIFS(主题清单!$B$2:$B$70,A13,主题清单!$J$2:$J$70,"已制作") -> 4 | H13: =F13-G13 -> 0
A14: 合计 | F14: =SUM(F2:F13) -> 69 | G14: =SUM(G2:G13) -> 53 | H14: =SUM(H2:H13) -> 16
A15: 完成率 | G15: =IF(F14=0,0,G14/F14) -> 0.76811594

Sheet 主题清单
A1: 编号 | B1: 类型 | C1: 情绪组 | D1: 暂定标题 | E1: 锚点（真实数据 / 计算） | F1: 翻转金句 | G1: 受众 | H1: 时长档 | I1: 推荐优先 | J1: 制作状态 | K1: 批次 | L1: 风格 | M1: 配音 | N1: 成片文件名
A2: A1 | B2: A 时间的力量 | C2: 🔴 塑危组（制造紧迫感） | D2: 高考还剩 226 天，你真正能用的只有多少小时？ | E2: 按今天算到 2027.6.7 是 226 天。依次扣掉睡觉、吃饭、上课、通勤，剩下的自主时间用"时间格子"一格格熄灭（日期自动按发布日更新） | F2: 倒计时上的数字很大，属于你的很少 | G2: 高三生+家长 | H2: M（30–60 秒） | I2: ⭐ | J2: 已制作 | K2: 第1批 | L2: 霓虹科技 | M2: 1号男声 | N2: A1_高考还剩226天_无配音.mp4 / _AI配音.mp4
A3: A2 | B3: A 时间的力量 | C3: 🔴 塑危组（制造紧迫感） | D3: 你的高中，只有 156 个格子 | E3: 人生 80 年 = 4,160 周，一周画一格；高中 3 年 = 156 格，只占 3.75%；已经过去的格子变暗 | F3: 每过一周，就有一格再也点不亮 | G3: 学生+家长 | H3: S（15–30 秒） | I3: ⭐ | J3: 已制作 | K3: 第0批 | L3: 暗金电影 | M3: 1号男声 | N3: A2_你的高中只有156个格子_无配音.mp4 / _AI配音.mp4
A4: A3 | B4: A 时间的力量 | C4: 🔴 塑危组（制造紧迫感） | D4: 每天 30 分钟，三年是多少？ | E4: 30 分钟 × 1,095 天 = 547.5 小时 ≈ 22.8 天不吃不睡 | F4: 时间不是没有，是碎掉了 | G4: 学生 | H4: S（15–30 秒） | J4: 未制作
A5: A4 | B5: A 时间的力量 | C5: 🔴 塑危组（制造紧迫感） | D5: 如果每天刷 2 小时手机 | E5: 2 小时 × 365 = 730 小时/年；× 1,095 天 = 2,190 小时 ≈ 91 天，比三个寒假（约 30 天/个）还多；每天少刷 30 分钟，三年多出 547 小时 | F5: 手机不会偷走你的时间，是你亲手交出去的 | G5: 学生+家长 | H5: S（15–30 秒） | J5: 已制作 | K5: 第5批 | L5: 玻璃拟态 | M5: 6号女声 | N5: A4_每天刷2小时手机三年是多少_无配音.mp4 / _AI配音.mp4
A6: A5 | B6: A 时间的力量 | C6: 🔴 塑危组（制造紧迫感） | D6: 高三还剩多少个周末？ | E6: 日历计算：从 2026-10-31（周六）到 2027-06-07 高考前共 32 个周末；其中含春节（2/6）、百日倒计时（2/27） | F6: 不是还有很久，是只剩 32 次 | G6: 高三生 | H6: S（15–30 秒） | J6: 已制作 | K6: 第5批 | L6: 杂志排版 | M6: 1号男声 | N6: A5_高三还剩多少个周末_无配音.mp4 / _AI配音.mp4
A7: A6 | B7: A 时间的力量 | C7: 🔴 塑危组（制造紧迫感） | D7: 时间是唯一不能充值的东西 | E7: 时间沙漏 vs 金钱进度条：钱可以挣回来，时间格子只能熄灭（熵增，不可逆） | F7: 你可以重考一次试，不能重过一年 | G7: 学生+家长 | H7: S（15–30 秒） | J7: 未制作
A8: B1 | B8: B 迈出第一步 | C8: 🟡 激励组（给动力） | D8: 为什么"开始"最难？物理早就告诉你了 | E8: 最大静摩擦力 > 滑动摩擦力：推动静止的箱子要更大的力，一旦动起来反而省力（受力分析动画 + 力的数值对比） | F8: 最费力的永远是第一下 | G8: 学生 | H8: M（30–60 秒） | I8: ⭐ | J8: 已制作 | K8: 第2批 | L8: 蓝图工程 | M8: 3号男声 | N8: B1_寒假第一天就停下_无配音.mp4 / _AI配音.mp4
A9: B2 | B9: B 迈出第一步 | C9: 🟡 激励组（给动力） | D9: 晚 30 天开始，差距永远追不回来 | E9: 两人同样每天进步 1%，一个晚 30 天开始：1.01³⁰ = 1.348，比例差永远 34.8%，绝对差越拉越大 | F9: 不是谁更努力，是谁先开始 | G9: 学生+家长 | H9: M（30–60 秒） | I9: ⭐ | J9: 已制作 | K9: 第0批 | L9: 信息图 | M9: 1号男声 | N9: B2_晚30天开始_无配音.mp4 / _AI配音.mp4
A10: B3 | B10: B 迈出第一步 | C10: 🟡 激励组（给动力） | D10: 一块骨牌，推倒一座大楼 | E10: Whitehead（1983）：一块骨牌能推倒约大 1.5 倍的骨牌；5 mm × 1.5^n：第 10 块 19 cm，第 20 块 11 m，第 30 块 639 m（上海中心 632 m） | F10: 第一块很小，但必须有人推 | G10: 学生 | H10: S（15–30 秒） | J10: 已制作 | K10: 第5批 | L10: 包豪斯几何 | M10: 2号男声 | N10: B3_一块骨牌推倒一座大楼_无配音.mp4 / _AI配音.mp4
A11: B4 | B11: B 迈出第一步 | C11: 🟡 激励组（给动力） | D11: 化学反应为什么需要"点火"？ | E11: 氢气与氧气常温几乎不反应、点燃爆鸣；能量—反应进程曲线：先越过活化能；催化剂降低能垒，不改变反应前后能量差 | F11: 开始总有一道坎，好方法就是你的催化剂 | G11: 学生 | H11: M（30–60 秒） | J11: 已制作 | K11: 第5批 | L11: 黑板粉笔 | M11: 3号男声 | N11: B4_化学反应为什么需要点火_无配音.mp4 / _AI配音.mp4
A12: B5 | B12: B 迈出第一步 | C12: 🟡 激励组（给动力） | D12: 惯性：不动的东西，会一直不动 | E12: 牛顿第一定律：没有外力，静止的物体保持静止 | F12: 等"想学的时候再学"，那一天不会自己来 | G12: 学生 | H12: S（15–30 秒） | J12: 未制作
A13: B6 | B13: B 迈出第一步 | C13: 🟡 激励组（给动力） | D13: 0 乘以任何数，都是 0 | E13: 计划 100 分 × 行动 0 = 0；计划 60 分 × 行动 1 = 60 | F13: 不完美的开始，好过完美的等待 | G13: 学生+家长 | H13: S（15–30 秒） | J13: 未制作
A14: C1 | B14: C 坚持到临界点 | C14: 🟡 激励组（给动力） | D14: 99℃ 和 100℃ | E14: 水从 0℃ 烧到 100℃ 要 418 J/g，变成蒸汽还要 2,257 J/g，是之前全部加热的 5.4 倍；温度计却一直停在 100℃ | F14: 最后一步，需要的力气最多，也最看不见 | G14: 学生 | H14: M（30–60 秒） | I14: ⭐ | J14: 已制作 | K14: 第0批 | L14: 暗金电影 | M14: 1号男声 | N14: C1_99℃和100℃_无配音.mp4 / _AI配音.mp4
A15: C2 | B15: C 坚持到临界点 | C15: 🟡 激励组（给动力） | D15: 成绩不涨，不代表你没进步 | E15: 冰在 0℃ 持续吸热、温度不变（熔化热 334 J/g，相当于从 -10℃ 升到 0℃ 所需热量的 16 倍），能量全部用在质变上 | F15: 平台期不是停滞，是正在融化 | G15: 学生（中等生） | H15: M（30–60 秒） | I15: ⭐ | J15: 已制作 | K15: 第1批 | L15: 冷蓝电影 | M15: 3号男声 | N15: C2_成绩不涨不代表你没进步_无配音.mp4 / _AI配音.mp4
A16: C3 | B16: C 坚持到临界点 | C16: 🟡 激励组（给动力） | D16: 荷叶第 29 天，只铺满一半 | E16: 荷叶每天翻倍、30 天铺满池塘：第 29 天是 50%，第 25 天只有 3.1% | F16: 大多数人，放弃在第 25 天 | G16: 学生 | H16: S（15–30 秒） | I16: ⭐ | J16: 已制作 | K16: 第1批 | L16: 新中式水墨 | M16: 6号女声 | N16: C3_荷叶第29天_无配音.mp4 / _AI配音.mp4
A17: C4 | B17: C 坚持到临界点 | C17: 🟡 激励组（给动力） | D17: 差一点，就飞不出地球 | E17: 第一宇宙速度 7.9 km/s：7.8 km/s 会落回地面，7.9 km/s 就能绕地飞行（轨道模拟） | F17: 差一点点和做到了，是两个世界 | G17: 学生 | H17: M（30–60 秒） | J17: 已制作 | K17: 第4批 | L17: 深空 | M17: 2号男声 | N17: C4_差一点就飞不出地球_无配音.mp4 / _AI配音.mp4
A18: C5 | B18: C 坚持到临界点 | C18: 🟡 激励组（给动力） | D18: 养成一个习惯，不是 21 天 | E18: Lally 等（2010）研究：平均 66 天，范围 18–254 天（曲线逐渐趋平） | F18: 第 21 天觉得难很正常，你只是还没到 | G18: 学生 | H18: S（15–30 秒） | J18: 已制作 | K18: 第2批 | L18: 杂志排版 | M18: 5号女声 | N18: C5_养成一个习惯要多少天_无配音.mp4 / _AI配音.mp4
A19: C6 | B19: C 坚持到临界点 | C19: 🟡 激励组（给动力） | D19: 学霸也在"58%"停留过 | E19: 渗流临界点 59.27%（参考 A 的改编版，把"单词/琴/稿子"换成"错题本/单词本/数学大题"） | F19: 在 58% 的时候，别走 | G19: 学生 | H19: L（60–120 秒） | J19: 未制作
A20: D1 | B20: D 每天一点点 | C20: 🟡 激励组（给动力） | D20: 1.01 和 0.99 | E20: 1.01³⁶⁵ = 37.8，0.99³⁶⁵ = 0.026，两条曲线分叉动画 | F20: 每天只差一点点，一年后差近 1,500 倍 | G20: 学生 | H20: S（15–30 秒） | I20: ⭐ | J20: 已制作 | K20: 第1批 | L20: 极简白 | M20: 5号女声 | N20: D1_1.01和0.99_无配音.mp4 / _AI配音.mp4
A21: D2 | B21: D 每天一点点 | C21: 🟡 激励组（给动力） | D21: 把纸对折 42 次 | E21: 0.1mm × 2⁴² ≈ 44 万公里，超过地月距离 38.4 万公里 | F21: 每一次都只是翻倍，最后一次到了月球 | G21: 学生 | H21: S（15–30 秒） | J21: 已制作 | K21: 第4批 | L21: 纸雕 | M21: 5号女声 | N21: D2_把纸对折42次_无配音.mp4 / _AI配音.mp4
A22: D3 | B22: D 每天一点点 | C22: 🟡 激励组（给动力） | D22: 高考 3000 个单词，其实只要一年 | E22: 课标要求约 3,000 词；每天 10 个，300 天背完（日历格子逐日点亮） | F22: 难的不是 3000，是每天的 10 个 | G22: 学生 | H22: S（15–30 秒） | J22: 已制作 | K22: 第4批 | L22: 手账笔记 | M22: 4号女声 | N22: D3_3000个单词其实只要一年_无配音.mp4 / _AI配音.mp4
A23: D4 | B23: D 每天一点点 | C23: 🟡 激励组（给动力） | D23: 每天多做一道题 | E23: 1 道 × 1,095 天 = 1,095 道 ≈ X 本练习册（叠起来的高度动画） | F23: 一道题改变不了什么，一千道可以 | G23: 学生 | H23: S（15–30 秒） | J23: 未制作
A24: D5 | B24: D 每天一点点 | C24: 🟡 激励组（给动力） | D24: 曲线下面的面积 | E24: 积分思想：每天一小段 dx，三年后是整片面积（高三数学向） | F24: 你看不见每一天，但它们全部算数 | G24: 高二高三生 | H24: M（30–60 秒） | J24: 已制作 | K24: 第4批 | L24: 黑板粉笔 | M24: 2号男声 | N24: D5_曲线下面的面积_无配音.mp4 / _AI配音.mp4
A25: E1 | B25: E 集中力量 | C25: 🔵 赋能组（给方法、给信心） | D25: 同样的阳光，为什么能点燃纸？ | E25: 凸透镜聚焦：同样的光能量集中到一点，温度大幅升高 | F25: 不是你不够亮，是你太分散 | G25: 学生+家长 | H25: S（15–30 秒） | I25: ⭐ | J25: 已制作 | K25: 第4批 | L25: 暗金电影 | M25: 4号女声 | N25: E1_同样的阳光为什么能点燃纸_无配音.mp4 / _AI配音.mp4
A26: E2 | B26: E 集中力量 | C26: 🔵 赋能组（给方法、给信心） | D26: 4 科各 15%，不如 1 科 60% | E26: 渗流的"密度"原理：同样数量的亮格分给 4 张网格都不通，收进 1 张就通了 | F26: 先打穿一科，再谈全面 | G26: 家长+学生 | H26: M（30–60 秒） | I26: ⭐ | J26: 已制作 | K26: 第2批 | L26: 暗金电影 | M26: 1号男声 | N26: E2_寒假别想全科都补_无配音.mp4 / _AI配音.mp4
A27: E3 | B27: E 集中力量 | C27: 🔵 赋能组（给方法、给信心） | D27: 钉子为什么能钉进墙？ | E27: 压强 P = F/S：同样的力，面积越小压强越大 | F27: 力气要用在一个点上 | G27: 学生 | H27: S（15–30 秒） | J27: 未制作
A28: E4 | B28: E 集中力量 | C28: 🔵 赋能组（给方法、给信心） | D28: 一心多用，偷走你 40% 的时间 | E28: APA（美国心理学会）引用研究：任务切换最多可损失 40% 的有效时间 | F28: 写作业时回一条消息，代价比你想的大 | G28: 学生+家长 | H28: S（15–30 秒） | J28: 已制作 | K28: 第4批 | L28: 蓝图工程 | M28: 3号男声 | N28: E4_边写作业边回消息代价有多大_无配音.mp4 / _AI配音.mp4
A29: E5 | B29: E 集中力量 | C29: 🔵 赋能组（给方法、给信心） | D29: 6 科各提 3 分 vs 1 科提 18 分 | E29: 同样 18 分，哪个更容易？用弱科的提分空间做对比 | F29: 做减法，是最快的加法 | G29: 家长 | H29: M（30–60 秒） | J29: 未制作
A30: E6 | B30: E 集中力量 | C30: 🔵 赋能组（给方法、给信心） | D30: 学习时，手机放哪？ | E30: Ward 等（2017）近 800 人实验：手机放在另一个房间的人测试表现最好，放桌上最差，即使静音朝下 | F30: 学习的时候，让手机离开房间 | G30: 学生+家长 | H30: M（30–60 秒） | J30: 已制作 | K30: 第3批 | L30: 霓虹科技 | M30: 2号男声 | N30: E6_学习时手机放哪_无配音.mp4 / _AI配音.mp4
A31: F1 | B31: F 方法与借力 | C31: 🔵 赋能组（给方法、给信心） | D31: 你背过的东西，一天后只剩 34% | E31: 艾宾浩斯遗忘曲线：20 分钟后 58%、1 小时 44%、1 天 34%、6 天 25%、31 天 21%；加入间隔复习后曲线被反复"拉回" | F31: 不是你记性差，是没在对的时间复习 | G31: 学生+家长 | H31: M（30–60 秒） | I31: ⭐ | J31: 已制作 | K31: 第1批 | L31: 手账笔记 | M31: 4号女声 | N31: F1_遗忘曲线_无配音.mp4 / _AI配音.mp4
A32: F2 | B32: F 方法与借力 | C32: 🔵 赋能组（给方法、给信心） | D32: 努力是一个向量 | E32: 有效分量 = 努力 × cosθ：方向偏 30°，损失 13%；偏 60°，损失一半；偏 90°，全部白费 | F32: 方向不对，越努力越远 | G32: 学生+家长 | H32: M（30–60 秒） | I32: ⭐ | J32: 已制作 | K32: 第1批 | L32: 蓝图工程 | M32: 2号男声 | N32: F2_努力是一个向量_无配音.mp4 / _AI配音.mp4
A33: F3 | B33: F 方法与借力 | C33: 🔵 赋能组（给方法、给信心） | D33: 给我一个支点 | E33: 杠杆平衡 F₁L₁ = F₂L₂：动力臂是阻力臂 6 倍，10 公斤撬起 60 公斤；相传阿基米德名言 | F33: 好老师和好方法，就是孩子的力臂 | G33: 家长 | H33: S（15–30 秒） | J33: 已制作 | K33: 第5批 | L33: 孔版印刷 | M33: 4号女声 | N33: F3_给我一个支点_无配音.mp4 / _AI配音.mp4
A34: F4 | B34: F 方法与借力 | C34: 🔵 赋能组（给方法、给信心） | D34: 站在巨人的肩膀上 | E34: 牛顿 1675 年信件原话；高中物理公式背后是几百年的积累（时间轴动画） | F34: 不必从零摸索，前人已经铺好了路 | G34: 学生+家长 | H34: M（30–60 秒） | J34: 未制作
A35: F5 | B35: F 方法与借力 | C35: 🔵 赋能组（给方法、给信心） | D35: AI 是怎么学会的？靠犯错 | E35: 梯度下降：小球沿误差曲面一步步滚到最低点，每一次错误都提供方向 | F35: 错题不是失败，是你的梯度 | G35: 学生 | H35: M（30–60 秒） | J35: 已制作 | K35: 第4批 | L35: 霓虹科技 | M35: 1号男声 | N35: F5_AI是靠犯错学会的_无配音.mp4 / _AI配音.mp4
A36: F6 | B36: F 方法与借力 | C36: 🔵 赋能组（给方法、给信心） | D36: 新学期目标，拆小了才能完成 | E36: Bandura & Schunk（1981）：42 页数学练习，'每次 6 页'的小目标组进步最快、最有信心 | F36: 大目标定方向，小目标给动力 | G36: 学生 | H36: M（30–60 秒） | J36: 已制作 | K36: 第3批 | L36: 手账笔记 | M36: 5号女声 | N36: F6_新学期目标拆小了才能完成_无配音.mp4 / _AI配音.mp4
A37: G1 | B37: G 差距与竞争 | C37: 🔴 塑危组（制造紧迫感） | D37: 1 分，能压倒多少人？ | E37: 正态分布：中间段分数最密集，中等生每多 1 分超过的人最多（钟形曲线 + 人群点阵） | F37: 越是中间的分数，1 分越值钱 | G37: 家长+中等生 | H37: M（30–60 秒） | I37: ⭐ | J37: 已制作 | K37: 第1批 | L37: 信息图 | M37: 1号男声 | N37: G1_1分能压倒多少人_无配音.mp4 / _AI配音.mp4
A38: G2 | B38: G 差距与竞争 | C38: 🔴 塑危组（制造紧迫感） | D38: 你在进步，名次为什么没变？ | E38: 相对运动：别人也在跑（参照系动画）；《爱丽丝镜中奇遇》："你必须拼命奔跑，才能留在原地" | F38: 原地踏步，就是后退 | G38: 学生+家长 | H38: S（15–30 秒） | I38: ⭐ | J38: 已制作 | K38: 第2批 | L38: 黑板粉笔 | M38: 3号男声 | N38: G2_寒假你进步了名次为什么没变_无配音.mp4 / _AI配音.mp4
A39: G3 | B39: G 差距与竞争 | C39: 🔴 塑危组（制造紧迫感） | D39: 差距是按"平方"拉大的 | E39: s = ½at²：两人加速度相差恒定，差距与时间平方成正比——第 1、2、3、10 个月差 1、4、9、100 步（示意） | F39: 现在的一点点，高考时是一大截 | G39: 学生+家长 | H39: M（30–60 秒） | J39: 已制作 | K39: 第5批 | L39: 信息图 | M39: 1号男声 | N39: G3_差距是按平方拉大的_无配音.mp4 / _AI配音.mp4
A40: G4 | B40: G 差距与竞争 | C40: 🔴 塑危组（制造紧迫感） | D40: 某省一分一段表里的 1 分 | E40: 真实一分一段表（需按目标省份提供数据）：600 分附近 1 分 = 数百人 | F40: 1 分，是一整个操场的人 | G40: 家长 | H40: S（15–30 秒） | J40: 未制作
...

Sheet 说明
A1: 用途 | B1: 高中销转短视频选题库：12 个类型、69 个主题（原规划 61 个 + 第 3 批新增 7 个 + 第 4 批新增 1 个，K4 换题）。每个主题都以一个真实的科学事实或算出来的数字作锚点，前 2/3 讲科学、后 1/3 翻转到高中生活。
A2: 情绪组 | B2: 🔴 塑危组：引流钩子、推课塑危、截杀；🟡 激励组：社群维护、促出勤、早晚安；🔵 赋能组：推课价值、异议处理、家长沟通。
A3: 时长档 | B3: S 15–30 秒（一个事实 + 一句金句）；M 30–60 秒（完整五段式）；L 60–120 秒（旗舰片）。成片实际时长含 4.2 秒品牌片尾。
A4: 推荐优先 | B4: ⭐ 为规划时建议优先制作的主题。
A5: 制作状态 | B5: 绿色底色 = 已制作（成片在仓库 studio/out/，每条含无配音版、AI 配音版、封面图）。可在本表手动更新状态，「类型总览」的统计会自动重算。
A6: 需提供数据 | B6: G4（一分一段表）需要目标省份的真实数据；J4（学员提分案例）需要真实学员数据。
A7: 数据红线 | B7: 不用伪科学励志梗：竹子定律、21 天养成习惯、学习金字塔、人只用了大脑 10%、金鱼记忆 7 秒。估算、示例、模拟数据在画面上都标注。
A8: 配音编号 | B8: 1 号男声沉稳、2 号男声清亮、3 号男声温和、4 号女声温柔、5 号女声明亮、6 号女声知性（试听：studio/out/配音音色试听.m4a）。
A9: 来源 | B9: docs/视频系列方案.md（V1，2026-10-24 确认）。
